Traceback (most recent call last):
  File "/usr/local/lib/python3.9/site-packages/jupyter_cache/executors/utils.py", line 51, in single_nb_execution
    executenb(
  File "/usr/local/lib/python3.9/site-packages/nbclient/client.py", line 1093, in execute
    return NotebookClient(nb=nb, resources=resources, km=km, **kwargs).execute()
  File "/usr/local/lib/python3.9/site-packages/nbclient/util.py", line 84, in wrapped
    return just_run(coro(*args, **kwargs))
  File "/usr/local/lib/python3.9/site-packages/nbclient/util.py", line 62, in just_run
    return loop.run_until_complete(coro)
  File "/usr/local/lib/python3.9/asyncio/base_events.py", line 642, in run_until_complete
    return future.result()
  File "/usr/local/lib/python3.9/site-packages/nbclient/client.py", line 559, in async_execute
    await self.async_execute_cell(
  File "/usr/local/lib/python3.9/site-packages/nbclient/client.py", line 854, in async_execute_cell
    self._check_raise_for_error(cell, exec_reply)
  File "/usr/local/lib/python3.9/site-packages/nbclient/client.py", line 756, in _check_raise_for_error
    raise CellExecutionError.from_cell_and_msg(cell, exec_reply_content)
nbclient.exceptions.CellExecutionError: An error occurred while executing the following cell:
------------------
vw = pyvw.vw("--search 0 --csoaa_ldf m --search_task hook --ring_size 1024 --quiet")
task = vw.init_search_task(CovingtonDepParserLDF)
#BUG: This currently does not work because oracle generation is incorrect (generates invalid oracle values)#for p in range(2): # do two passes over the training data
#    task.learn(my_dataset)
#print(task.predict( [(w,-1) for w in "the monster ate a sandwich".split()] ))
------------------

[0;31m---------------------------------------------------------------------------[0m
[0;31mRuntimeError[0m                              Traceback (most recent call last)
[0;32m/tmp/ipykernel_185/3119859344.py[0m in [0;36m<module>[0;34m[0m
[0;32m----> 1[0;31m [0mvw[0m [0;34m=[0m [0mpyvw[0m[0;34m.[0m[0mvw[0m[0;34m([0m[0;34m"--search 0 --csoaa_ldf m --search_task hook --ring_size 1024 --quiet"[0m[0;34m)[0m[0;34m[0m[0;34m[0m[0m
[0m[1;32m      2[0m [0mtask[0m [0;34m=[0m [0mvw[0m[0;34m.[0m[0minit_search_task[0m[0;34m([0m[0mCovingtonDepParserLDF[0m[0;34m)[0m[0;34m[0m[0;34m[0m[0m
[1;32m      3[0m [0;31m#BUG: This currently does not work because oracle generation is incorrect (generates invalid oracle values)#for p in range(2): # do two passes over the training data[0m[0;34m[0m[0;34m[0m[0m
[1;32m      4[0m [0;31m#    task.learn(my_dataset)[0m[0;34m[0m[0;34m[0m[0m
[1;32m      5[0m [0;31m#print(task.predict( [(w,-1) for w in "the monster ate a sandwich".split()] ))[0m[0;34m[0m[0;34m[0m[0m

[0;32m/usr/local/lib/python3.9/site-packages/vowpalwabbit/pyvw.py[0m in [0;36m__init__[0;34m(self, arg_str, enable_logging, **kw)[0m
[1;32m    365[0m             [0msuper[0m[0;34m([0m[0mvw[0m[0;34m,[0m [0mself[0m[0;34m)[0m[0;34m.[0m[0m__init__[0m[0;34m([0m[0;34m" "[0m[0;34m.[0m[0mjoin[0m[0;34m([0m[0ml[0m[0;34m)[0m[0;34m,[0m [0mself[0m[0;34m.[0m[0mlog_wrapper[0m[0;34m)[0m[0;34m[0m[0;34m[0m[0m
[1;32m    366[0m         [0;32melse[0m[0;34m:[0m[0;34m[0m[0;34m[0m[0m
[0;32m--> 367[0;31m             [0msuper[0m[0;34m([0m[0mvw[0m[0;34m,[0m [0mself[0m[0;34m)[0m[0;34m.[0m[0m__init__[0m[0;34m([0m[0;34m" "[0m[0;34m.[0m[0mjoin[0m[0;34m([0m[0ml[0m[0;34m)[0m[0;34m)[0m[0;34m[0m[0;34m[0m[0m
[0m[1;32m    368[0m         [0mself[0m[0;34m.[0m[0minit[0m [0;34m=[0m [0;32mTrue[0m[0;34m[0m[0;34m[0m[0m
[1;32m    369[0m [0;34m[0m[0m

[0;31mRuntimeError[0m: Tried to use a multiline reduction as a singleline reduction. Name: shared_feature_merger
RuntimeError: Tried to use a multiline reduction as a singleline reduction. Name: shared_feature_merger

